<?xml version="1.0" encoding="utf-8"?>
<!-- This URDF was automatically created by SolidWorks to URDF Exporter! Originally created by Stephen Brawner (brawner@gmail.com) 
     Commit Version: 1.5.1-0-g916b5db  Build Version: 1.5.7152.31018
     For more information, please see http://wiki.ros.org/sw_urdf_exporter -->
<robot
  name="16_degree">
  <link
    name="base_link">
    <inertial>
      <origin
        xyz="6.9389E-18 5.308E-08 1.7347E-18"
        rpy="0 0 0" />
      <mass
        value="2.942" />
      <inertia
        ixx="0.0106004"
        ixy="-1.4228E-19"
        ixz="-1.0163E-10"
        iyy="0.0431073"
        iyz="5.1841E-18"
        izz="0.0510803" />
    </inertial>
    <visual>
      <origin
        xyz="0 0 0"
        rpy="0 0 0" />
      <geometry>
        <mesh
          filename="package://16_degree/meshes/base_link.STL" />
      </geometry>
      <material
        name="">
        <color
          rgba="1 1 1 1" />
      </material>
    </visual>
    <collision>
      <origin
        xyz="0 0 0"
        rpy="0 0 0" />
      <geometry>
        <mesh
          filename="package://16_degree/meshes/base_link.STL" />
      </geometry>
    </collision>
  </link>
  <link
    name="left_front_link">
    <inertial>
      <origin
        xyz="-1.7488E-08 0.05683 -0.036011"
        rpy="0 0 0" />
      <mass
        value="0.095" />
      <inertia
        ixx="0.0002672"
        ixy="7.4034E-10"
        ixz="7.5294E-10"
        iyy="0.0000540"
        iyz="2.33E-05"
        izz="0.0002642" />
    </inertial>
    <visual>
      <origin
        xyz="0 0 0"
        rpy="0 0 0" />
      <geometry>
        <mesh
          filename="package://16_degree/meshes/left_front_link.STL" />
      </geometry>
      <material
        name="">
        <color
          rgba="1 1 1 1" />
      </material>
    </visual>
    <collision>
      <origin
        xyz="0 0 0"
        rpy="0 0 0" />
      <geometry>
        <mesh
          filename="package://16_degree/meshes/left_front_link.STL" />
      </geometry>
    </collision>
  </link>
  <joint
    name="left_front_leg"
    type="continuous">
    <origin
      xyz="0.15839 0.09901 0"
      rpy="1.85 1.5708 0" />
    <parent
      link="base_link" />
    <child
      link="left_front_link" />
    <axis
      xyz="0 0 -1" />
    <limit
      effort="5"
      velocity="487" />
  </joint>
  <link
    name="right_front_link">
    <inertial>
      <origin
        xyz="1.7488E-08 0.05683 0.036011"
        rpy="0 0 0" />
      <mass
        value="0.095" />
      <inertia
        ixx="0.0002672"
        ixy="-7.4034E-10"
        ixz="7.5294E-10"
        iyy="0.0000540"
        iyz="-2.33E-05"
        izz="0.0002642" />
    </inertial>
    <visual>
      <origin
        xyz="0 0 0"
        rpy="0 0 0" />
      <geometry>
        <mesh
          filename="package://16_degree/meshes/right_front_link.STL" />
      </geometry>
      <material
        name="">
        <color
          rgba="1 1 1 1" />
      </material>
    </visual>
    <collision>
      <origin
        xyz="0 0 0"
        rpy="0 0 0" />
      <geometry>
        <mesh
          filename="package://16_degree/meshes/right_front_link.STL" />
      </geometry>
    </collision>
  </link>
  <joint
    name="right_front_leg"
    type="continuous">
    <origin
      xyz="0.15839 -0.09901 0"
      rpy="1.2915 1.5708 0" />
    <parent
      link="base_link" />
    <child
      link="right_front_link" />
    <axis
      xyz="0 0 1" />
    <limit
      effort="5"
      velocity="487" />
  </joint>
  <link
    name="right_back_link">
    <inertial>
      <origin
        xyz="8.6114E-08 0.056834 0.03601"
        rpy="0 0 0" />
      <mass
        value="0.095" />
      <inertia
        ixx="0.0002672"
        ixy="-5.4276E-10"
        ixz="2.4861E-10"
        iyy="0.0000540"
        iyz="-2.33E-05"
        izz="0.0002642" />
    </inertial>
    <visual>
      <origin
        xyz="0 0 0"
        rpy="0 0 0" />
      <geometry>
        <mesh
          filename="package://16_degree/meshes/right_back_link.STL" />
      </geometry>
      <material
        name="">
        <color
          rgba="1 1 1 1" />
      </material>
    </visual>
    <collision>
      <origin
        xyz="0 0 0"
        rpy="0 0 0" />
      <geometry>
        <mesh
          filename="package://16_degree/meshes/right_back_link.STL" />
      </geometry>
    </collision>
  </link>
  <joint
    name="right_back_leg"
    type="continuous">
    <origin
      xyz="-0.15839 -0.09901 0"
      rpy="1.85 1.5708 0" />
    <parent
      link="base_link" />
    <child
      link="right_back_link" />
    <axis
      xyz="0 0 1" />
    <limit
      effort="5"
      velocity="487" />
  </joint>
  <link
    name="left_back_link">
    <inertial>
      <origin
        xyz="-8.6114E-08 0.056834 -0.03601"
        rpy="0 0 0" />
      <mass
        value="0.095" />
      <inertia
        ixx="0.0002672"
        ixy="5.4276E-10"
        ixz="2.4861E-10"
        iyy="0.0000540"
        iyz="2.33E-05"
        izz="0.0002642" />
    </inertial>
    <visual>
      <origin
        xyz="0 0 0"
        rpy="0 0 0" />
      <geometry>
        <mesh
          filename="package://16_degree/meshes/left_back_link.STL" />
      </geometry>
      <material
        name="">
        <color
          rgba="1 1 1 1" />
      </material>
    </visual>
    <collision>
      <origin
        xyz="0 0 0"
        rpy="0 0 0" />
      <geometry>
        <mesh
          filename="package://16_degree/meshes/left_back_link.STL" />
      </geometry>
    </collision>
  </link>
  <joint
    name="left_back_leg"
    type="continuous">
    <origin
      xyz="-0.15839 0.09901 0"
      rpy="1.2915 1.5708 0" />
    <parent
      link="base_link" />
    <child
      link="left_back_link" />
    <axis
      xyz="0 0 -1" />
    <limit
      effort="5"
      velocity="487" />
  </joint>
</robot>