<?xml version="1.0" encoding="utf-8"?>
<!-- This URDF was automatically created by SolidWorks to URDF Exporter! Originally created by Stephen Brawner (brawner@gmail.com) 
     Commit Version: 1.5.1-0-g916b5db  Build Version: 1.5.7152.31018
     For more information, please see http://wiki.ros.org/sw_urdf_exporter -->
<robot
  name="30_degree">
  <link
    name="base_link">
    <inertial>
      <origin
        xyz="-6.245E-17 5.4293E-08 1.6547E-08"
        rpy="0 0 0" />
      <mass
        value="2.942" />
      <inertia
        ixx="0.0092249"
        ixy="7.0243E-09"
        ixz="-1.5154E-10"
        iyy="0.0495397"
        iyz="7.3486E-19"
        izz="0.0563174" />
    </inertial>
    <visual>
      <origin
        xyz="0 0 0"
        rpy="0 0 0" />
      <geometry>
        <mesh
          filename="package://30_degree/meshes/base_link.STL" />
      </geometry>
      <material
        name="">
        <color
          rgba="1 1 1 1" />
      </material>
    </visual>
    <collision>
      <origin
        xyz="0 0 0"
        rpy="0 0 0" />
      <geometry>
        <mesh
          filename="package://30_degree/meshes/base_link.STL" />
      </geometry>
    </collision>
  </link>
  <link
    name="left_front_link">
    <inertial>
      <origin
        xyz="-8.8303E-08 0.056834 -0.03601"
        rpy="0 0 0" />
      <mass
        value="0.092" />
      <inertia
        ixx="0.0002604"
        ixy="5.2575E-10"
        ixz="2.3875E-10"
        iyy="0.0000526"
        iyz="2.27E-05"
        izz="0.0002575" />
    </inertial>
    <visual>
      <origin
        xyz="0 0 0"
        rpy="0 0 0" />
      <geometry>
        <mesh
          filename="package://30_degree/meshes/left_front_link.STL" />
      </geometry>
      <material
        name="">
        <color
          rgba="1 1 1 1" />
      </material>
    </visual>
    <collision>
      <origin
        xyz="0 0 0"
        rpy="0 0 0" />
      <geometry>
        <mesh
          filename="package://30_degree/meshes/left_front_link.STL" />
      </geometry>
    </collision>
  </link>
  <joint
    name="left_front_leg"
    type="continuous">
    <origin
      xyz="0.1815 0.089201 0"
      rpy="2.0944 1.5708 0" />
    <parent
      link="base_link" />
    <child
      link="left_front_link" />
    <axis
      xyz="0 0 -1" />
    <limit
      effort="5"
      velocity="487" />
  </joint>
  <link
    name="right_front_link">
    <inertial>
      <origin
        xyz="8.8303E-08 0.056834 0.03601"
        rpy="0 0 0" />
      <mass
        value="0.092" />
      <inertia
        ixx="0.0002604"
        ixy="-5.2575E-10"
        ixz="2.3875E-10"
        iyy="0.0000526"
        iyz="-2.27E-05"
        izz="0.0002575" />
    </inertial>
    <visual>
      <origin
        xyz="0 0 0"
        rpy="0 0 0" />
      <geometry>
        <mesh
          filename="package://30_degree/meshes/right_front_link.STL" />
      </geometry>
      <material
        name="">
        <color
          rgba="1 1 1 1" />
      </material>
    </visual>
    <collision>
      <origin
        xyz="0 0 0"
        rpy="0 0 0" />
      <geometry>
        <mesh
          filename="package://30_degree/meshes/right_front_link.STL" />
      </geometry>
    </collision>
  </link>
  <joint
    name="right_front_leg"
    type="continuous">
    <origin
      xyz="0.1815 -0.089201 0"
      rpy="1.0472 1.5708 0" />
    <parent
      link="base_link" />
    <child
      link="right_front_link" />
    <axis
      xyz="0 0 1" />
    <limit
      effort="5"
      velocity="487" />
  </joint>
  <link
    name="right_back_link">
    <inertial>
      <origin
        xyz="8.1005E-08 0.056834 0.03601"
        rpy="0 0 0" />
      <mass
        value="0.092" />
      <inertia
        ixx="0.0002604"
        ixy="-5.043E-10"
        ixz="1.5614E-10"
        iyy="0.0000526"
        iyz="-2.27E-05"
        izz="0.0002575" />
    </inertial>
    <visual>
      <origin
        xyz="0 0 0"
        rpy="0 0 0" />
      <geometry>
        <mesh
          filename="package://30_degree/meshes/right_back_link.STL" />
      </geometry>
      <material
        name="">
        <color
          rgba="1 1 1 1" />
      </material>
    </visual>
    <collision>
      <origin
        xyz="0 0 0"
        rpy="0 0 0" />
      <geometry>
        <mesh
          filename="package://30_degree/meshes/right_back_link.STL" />
      </geometry>
    </collision>
  </link>
  <joint
    name="right_back_leg"
    type="continuous">
    <origin
      xyz="-0.1815 -0.089201 0"
      rpy="2.0944 1.5708 0" />
    <parent
      link="base_link" />
    <child
      link="right_back_link" />
    <axis
      xyz="0 0 1" />
    <limit
      effort="5"
      velocity="487" />
  </joint>
  <link
    name="left_back_link">
    <inertial>
      <origin
        xyz="-8.1005E-08 0.056834 -0.03601"
        rpy="0 0 0" />
      <mass
        value="0.092" />
      <inertia
        ixx="0.0002604"
        ixy="5.043E-10"
        ixz="1.5614E-10"
        iyy="0.0000526"
        iyz="2.27E-05"
        izz="0.0002575" />
    </inertial>
    <visual>
      <origin
        xyz="0 0 0"
        rpy="0 0 0" />
      <geometry>
        <mesh
          filename="package://30_degree/meshes/left_back_link.STL" />
      </geometry>
      <material
        name="">
        <color
          rgba="1 1 1 1" />
      </material>
    </visual>
    <collision>
      <origin
        xyz="0 0 0"
        rpy="0 0 0" />
      <geometry>
        <mesh
          filename="package://30_degree/meshes/left_back_link.STL" />
      </geometry>
    </collision>
  </link>
  <joint
    name="left_back_leg"
    type="continuous">
    <origin
      xyz="-0.1815 0.089201 0"
      rpy="1.0472 1.5708 0" />
    <parent
      link="base_link" />
    <child
      link="left_back_link" />
    <axis
      xyz="0 0 -1" />
    <limit
      effort="5"
      velocity="487" />
  </joint>
</robot>