<?xml version='1.0' encoding='UTF-8'?>
<robot name="robot">
  <link name="body">
    <inertial>
      <origin xyz="0.0 0.0 0.0" rpy="0.0 0.0 0.0"/>
      <mass value="0.376970596380699"/>
      <inertia ixx="0.0046768329806119325" ixy="-2.2549710462289577e-09" ixz="-5.585951885002455e-09" iyy="0.0053812819700991875" iyz="-1.7144668172985471e-09" izz="0.001553697140572674"/>
    </inertial>
    <visual>
      <origin xyz="0.0 0.0 0.0" rpy="0.0 0.0 0.0"/>
      <geometry>
        <mesh filename="mesh/body.obj"/>
      </geometry>
      <material name="#ffffffff">
        <color rgba="1 1 1 1"/>
      </material>
    </visual>
    <collision>
      <origin xyz="0.0 0.0 0.0" rpy="0.0 0.0 0.0"/>
      <geometry>
        <mesh filename="mesh/body.obj"/>
      </geometry>
    </collision>
  </link>
  <link name="lf_m1">
    <inertial>
      <origin xyz="0.0 0.0 0.0" rpy="0.0 0.0 0.0"/>
      <mass value="0.03257455734158853"/>
      <inertia ixx="2.30860579309019e-05" ixy="-3.017172025783328e-10" ixz="6.14426220694766e-12" iyy="1.592727621325853e-05" iyz="-3.5801482125832484e-12" izz="1.592782531081773e-05"/>
    </inertial>
    <visual>
      <origin xyz="0.0 0.0 0.0" rpy="0.0 0.0 0.0"/>
      <geometry>
        <mesh filename="mesh/lf_m1.obj"/>
      </geometry>
      <material name="#ffffffff">
        <color rgba="1 1 1 1"/>
      </material>
    </visual>
    <collision>
      <origin xyz="0.0 0.0 0.0" rpy="0.0 0.0 0.0"/>
      <geometry>
        <mesh filename="mesh/lf_m1.obj"/>
      </geometry>
    </collision>
  </link>
  <link name="lf_hip">
    <inertial>
      <origin xyz="0.0 0.0 0.0" rpy="0.0 0.0 0.0"/>
      <mass value="0.03004188265707728"/>
      <inertia ixx="2.9411473822971713e-05" ixy="1.2390582935298588e-06" ixz="1.3485851429965568e-10" iyy="5.0921318299200916e-05" iyz="-4.874777577245254e-11" izz="3.3715613520396384e-05"/>
    </inertial>
    <visual>
      <origin xyz="0.0 0.0 0.0" rpy="0.0 0.0 0.0"/>
      <geometry>
        <mesh filename="mesh/lf_hip.obj"/>
      </geometry>
      <material name="#ffffffff">
        <color rgba="1 1 1 1"/>
      </material>
    </visual>
    <collision>
      <origin xyz="0.0 0.0 0.0" rpy="0.0 0.0 0.0"/>
      <geometry>
        <mesh filename="mesh/lf_hip.obj"/>
      </geometry>
    </collision>
  </link>
  <link name="lf_m2">
    <inertial>
      <origin xyz="0.0 0.0 0.0" rpy="0.0 0.0 0.0"/>
      <mass value="0.03257455734158853"/>
      <inertia ixx="2.30860579309019e-05" ixy="-3.017172025783328e-10" ixz="6.14426220694766e-12" iyy="1.592727621325853e-05" iyz="-3.5801482125832484e-12" izz="1.592782531081773e-05"/>
    </inertial>
    <visual>
      <origin xyz="0.0 0.0 0.0" rpy="0.0 0.0 0.0"/>
      <geometry>
        <mesh filename="mesh/lf_m2.obj"/>
      </geometry>
      <material name="#ffffffff">
        <color rgba="1 1 1 1"/>
      </material>
    </visual>
    <collision>
      <origin xyz="0.0 0.0 0.0" rpy="0.0 0.0 0.0"/>
      <geometry>
        <mesh filename="mesh/lf_m2.obj"/>
      </geometry>
    </collision>
  </link>
  <link name="lf_tc">
    <inertial>
      <origin xyz="0.0 0.0 0.0" rpy="0.0 0.0 0.0"/>
      <mass value="0.005815865339497284"/>
      <inertia ixx="3.943871513347597e-06" ixy="-8.801990579595257e-11" ixz="-1.05332769726045e-06" iyy="4.060625301326516e-06" iyz="-2.6869372681749636e-11" izz="2.7234200311580347e-06"/>
    </inertial>
    <visual>
      <origin xyz="0.0 0.0 0.0" rpy="0.0 0.0 0.0"/>
      <geometry>
        <mesh filename="mesh/lf_tc.obj"/>
      </geometry>
      <material name="#ffffffff">
        <color rgba="1 1 1 1"/>
      </material>
    </visual>
    <collision>
      <origin xyz="0.0 0.0 0.0" rpy="0.0 0.0 0.0"/>
      <geometry>
        <mesh filename="mesh/lf_tc.obj"/>
      </geometry>
    </collision>
  </link>
  <link name="lf_thigh">
    <inertial>
      <origin xyz="0.0 0.0 0.0" rpy="0.0 0.0 0.0"/>
      <mass value="0.056003570757274454"/>
      <inertia ixx="0.00012076904408054403" ixy="2.2435575170364517e-10" ixz="-9.893221423453491e-06" iyy="0.00010674518099689661" iyz="4.6333101083951687e-10" izz="4.647764726325559e-05"/>
    </inertial>
    <visual>
      <origin xyz="0.0 0.0 0.0" rpy="0.0 0.0 0.0"/>
      <geometry>
        <mesh filename="mesh/lf_thigh.obj"/>
      </geometry>
      <material name="#ffffffff">
        <color rgba="1 1 1 1"/>
      </material>
    </visual>
    <collision>
      <origin xyz="0.0 0.0 0.0" rpy="0.0 0.0 0.0"/>
      <geometry>
        <mesh filename="mesh/lf_thigh.obj"/>
      </geometry>
    </collision>
  </link>
  <link name="lf_m3">
    <inertial>
      <origin xyz="0.0 0.0 0.0" rpy="0.0 0.0 0.0"/>
      <mass value="0.03257455734158853"/>
      <inertia ixx="2.30860579309019e-05" ixy="-3.017172025783328e-10" ixz="6.14426220694766e-12" iyy="1.592727621325853e-05" iyz="-3.5801482125832484e-12" izz="1.592782531081773e-05"/>
    </inertial>
    <visual>
      <origin xyz="0.0 0.0 0.0" rpy="0.0 0.0 0.0"/>
      <geometry>
        <mesh filename="mesh/lf_m3.obj"/>
      </geometry>
      <material name="#ffffffff">
        <color rgba="1 1 1 1"/>
      </material>
    </visual>
    <collision>
      <origin xyz="0.0 0.0 0.0" rpy="0.0 0.0 0.0"/>
      <geometry>
        <mesh filename="mesh/lf_m3.obj"/>
      </geometry>
    </collision>
  </link>
  <link name="lf_sc">
    <inertial>
      <origin xyz="0.0 0.0 0.0" rpy="0.0 0.0 0.0"/>
      <mass value="0.004450137728878035"/>
      <inertia ixx="2.9370575854857886e-06" ixy="-3.0650854109537005e-13" ixz="-6.649014992215239e-07" iyy="2.9183966735791384e-06" iyz="-1.7493508853044012e-11" izz="1.3045258593510258e-06"/>
    </inertial>
    <visual>
      <origin xyz="0.0 0.0 0.0" rpy="0.0 0.0 0.0"/>
      <geometry>
        <mesh filename="mesh/lf_sc.obj"/>
      </geometry>
      <material name="#ffffffff">
        <color rgba="1 1 1 1"/>
      </material>
    </visual>
    <collision>
      <origin xyz="0.0 0.0 0.0" rpy="0.0 0.0 0.0"/>
      <geometry>
        <mesh filename="mesh/lf_sc.obj"/>
      </geometry>
    </collision>
  </link>
  <link name="lf_shank">
    <inertial>
      <origin xyz="0.0 0.0 0.0" rpy="0.0 0.0 0.0"/>
      <mass value="0.03565706349044272"/>
      <inertia ixx="4.530203891320738e-05" ixy="5.4462048756476605e-11" ixz="-1.7302586215760279e-09" iyy="4.519901322498138e-05" iyz="-9.852422125957808e-11" izz="1.203871510718817e-05"/>
    </inertial>
    <visual>
      <origin xyz="0.0 0.0 0.0" rpy="0.0 0.0 0.0"/>
      <geometry>
        <mesh filename="mesh/lf_shank.obj"/>
      </geometry>
      <material name="#ffffffff">
        <color rgba="1 1 1 1"/>
      </material>
    </visual>
    <collision>
      <origin xyz="0.0 0.0 0.0" rpy="0.0 0.0 0.0"/>
      <geometry>
        <mesh filename="mesh/lf_shank.obj"/>
      </geometry>
    </collision>
  </link>
  <link name="rf_m1">
    <inertial>
      <origin xyz="0.0 0.0 0.0" rpy="0.0 0.0 0.0"/>
      <mass value="0.03257455734158853"/>
      <inertia ixx="2.30860579309019e-05" ixy="-3.017172025783328e-10" ixz="6.14426220694766e-12" iyy="1.592727621325853e-05" iyz="-3.5801482125832484e-12" izz="1.592782531081773e-05"/>
    </inertial>
    <visual>
      <origin xyz="0.0 0.0 0.0" rpy="0.0 0.0 0.0"/>
      <geometry>
        <mesh filename="mesh/rf_m1.obj"/>
      </geometry>
      <material name="#ffffffff">
        <color rgba="1 1 1 1"/>
      </material>
    </visual>
    <collision>
      <origin xyz="0.0 0.0 0.0" rpy="0.0 0.0 0.0"/>
      <geometry>
        <mesh filename="mesh/rf_m1.obj"/>
      </geometry>
    </collision>
  </link>
  <link name="rf_hip">
    <inertial>
      <origin xyz="0.0 0.0 0.0" rpy="0.0 0.0 0.0"/>
      <mass value="0.03004188265707728"/>
      <inertia ixx="2.9411473822971713e-05" ixy="1.2390582935298588e-06" ixz="1.3485851429965568e-10" iyy="5.0921318299200916e-05" iyz="-4.874777577245254e-11" izz="3.3715613520396384e-05"/>
    </inertial>
    <visual>
      <origin xyz="0.0 0.0 0.0" rpy="0.0 0.0 0.0"/>
      <geometry>
        <mesh filename="mesh/rf_hip.obj"/>
      </geometry>
      <material name="#ffffffff">
        <color rgba="1 1 1 1"/>
      </material>
    </visual>
    <collision>
      <origin xyz="0.0 0.0 0.0" rpy="0.0 0.0 0.0"/>
      <geometry>
        <mesh filename="mesh/rf_hip.obj"/>
      </geometry>
    </collision>
  </link>
  <link name="rf_m2">
    <inertial>
      <origin xyz="0.0 0.0 0.0" rpy="0.0 0.0 0.0"/>
      <mass value="0.03257455734158853"/>
      <inertia ixx="2.30860579309019e-05" ixy="-3.017172025783328e-10" ixz="6.14426220694766e-12" iyy="1.592727621325853e-05" iyz="-3.5801482125832484e-12" izz="1.592782531081773e-05"/>
    </inertial>
    <visual>
      <origin xyz="0.0 0.0 0.0" rpy="0.0 0.0 0.0"/>
      <geometry>
        <mesh filename="mesh/rf_m2.obj"/>
      </geometry>
      <material name="#ffffffff">
        <color rgba="1 1 1 1"/>
      </material>
    </visual>
    <collision>
      <origin xyz="0.0 0.0 0.0" rpy="0.0 0.0 0.0"/>
      <geometry>
        <mesh filename="mesh/rf_m2.obj"/>
      </geometry>
    </collision>
  </link>
  <link name="rf_tc">
    <inertial>
      <origin xyz="0.0 0.0 0.0" rpy="0.0 0.0 0.0"/>
      <mass value="0.005815865339497284"/>
      <inertia ixx="3.943871513347597e-06" ixy="-8.801990579595257e-11" ixz="-1.05332769726045e-06" iyy="4.060625301326516e-06" iyz="-2.6869372681749636e-11" izz="2.7234200311580347e-06"/>
    </inertial>
    <visual>
      <origin xyz="0.0 0.0 0.0" rpy="0.0 0.0 0.0"/>
      <geometry>
        <mesh filename="mesh/rf_tc.obj"/>
      </geometry>
      <material name="#ffffffff">
        <color rgba="1 1 1 1"/>
      </material>
    </visual>
    <collision>
      <origin xyz="0.0 0.0 0.0" rpy="0.0 0.0 0.0"/>
      <geometry>
        <mesh filename="mesh/rf_tc.obj"/>
      </geometry>
    </collision>
  </link>
  <link name="rf_thigh">
    <inertial>
      <origin xyz="0.0 0.0 0.0" rpy="0.0 0.0 0.0"/>
      <mass value="0.056003570757274454"/>
      <inertia ixx="0.00012076904408054403" ixy="2.2435575170364517e-10" ixz="-9.893221423453491e-06" iyy="0.00010674518099689661" iyz="4.6333101083951687e-10" izz="4.647764726325559e-05"/>
    </inertial>
    <visual>
      <origin xyz="0.0 0.0 0.0" rpy="0.0 0.0 0.0"/>
      <geometry>
        <mesh filename="mesh/rf_thigh.obj"/>
      </geometry>
      <material name="#ffffffff">
        <color rgba="1 1 1 1"/>
      </material>
    </visual>
    <collision>
      <origin xyz="0.0 0.0 0.0" rpy="0.0 0.0 0.0"/>
      <geometry>
        <mesh filename="mesh/rf_thigh.obj"/>
      </geometry>
    </collision>
  </link>
  <link name="rf_m3">
    <inertial>
      <origin xyz="0.0 0.0 0.0" rpy="0.0 0.0 0.0"/>
      <mass value="0.03257455734158853"/>
      <inertia ixx="2.30860579309019e-05" ixy="-3.017172025783328e-10" ixz="6.14426220694766e-12" iyy="1.592727621325853e-05" iyz="-3.5801482125832484e-12" izz="1.592782531081773e-05"/>
    </inertial>
    <visual>
      <origin xyz="0.0 0.0 0.0" rpy="0.0 0.0 0.0"/>
      <geometry>
        <mesh filename="mesh/rf_m3.obj"/>
      </geometry>
      <material name="#ffffffff">
        <color rgba="1 1 1 1"/>
      </material>
    </visual>
    <collision>
      <origin xyz="0.0 0.0 0.0" rpy="0.0 0.0 0.0"/>
      <geometry>
        <mesh filename="mesh/rf_m3.obj"/>
      </geometry>
    </collision>
  </link>
  <link name="rf_sc">
    <inertial>
      <origin xyz="0.0 0.0 0.0" rpy="0.0 0.0 0.0"/>
      <mass value="0.004450137728878035"/>
      <inertia ixx="2.9370575854857886e-06" ixy="-3.0650854109537005e-13" ixz="-6.649014992215239e-07" iyy="2.9183966735791384e-06" iyz="-1.7493508853044012e-11" izz="1.3045258593510258e-06"/>
    </inertial>
    <visual>
      <origin xyz="0.0 0.0 0.0" rpy="0.0 0.0 0.0"/>
      <geometry>
        <mesh filename="mesh/rf_sc.obj"/>
      </geometry>
      <material name="#ffffffff">
        <color rgba="1 1 1 1"/>
      </material>
    </visual>
    <collision>
      <origin xyz="0.0 0.0 0.0" rpy="0.0 0.0 0.0"/>
      <geometry>
        <mesh filename="mesh/rf_sc.obj"/>
      </geometry>
    </collision>
  </link>
  <link name="rf_shank">
    <inertial>
      <origin xyz="0.0 0.0 0.0" rpy="0.0 0.0 0.0"/>
      <mass value="0.03565706349044272"/>
      <inertia ixx="4.530203891320738e-05" ixy="5.4462048756476605e-11" ixz="-1.7302586215760279e-09" iyy="4.519901322498138e-05" iyz="-9.852422125957808e-11" izz="1.203871510718817e-05"/>
    </inertial>
    <visual>
      <origin xyz="0.0 0.0 0.0" rpy="0.0 0.0 0.0"/>
      <geometry>
        <mesh filename="mesh/rf_shank.obj"/>
      </geometry>
      <material name="#ffffffff">
        <color rgba="1 1 1 1"/>
      </material>
    </visual>
    <collision>
      <origin xyz="0.0 0.0 0.0" rpy="0.0 0.0 0.0"/>
      <geometry>
        <mesh filename="mesh/rf_shank.obj"/>
      </geometry>
    </collision>
  </link>
  <link name="lb_m1">
    <inertial>
      <origin xyz="0.0 0.0 0.0" rpy="0.0 0.0 0.0"/>
      <mass value="0.03257455734158853"/>
      <inertia ixx="2.30860579309019e-05" ixy="-3.017172025783328e-10" ixz="6.14426220694766e-12" iyy="1.592727621325853e-05" iyz="-3.5801482125832484e-12" izz="1.592782531081773e-05"/>
    </inertial>
    <visual>
      <origin xyz="0.0 0.0 0.0" rpy="0.0 0.0 0.0"/>
      <geometry>
        <mesh filename="mesh/lb_m1.obj"/>
      </geometry>
      <material name="#ffffffff">
        <color rgba="1 1 1 1"/>
      </material>
    </visual>
    <collision>
      <origin xyz="0.0 0.0 0.0" rpy="0.0 0.0 0.0"/>
      <geometry>
        <mesh filename="mesh/lb_m1.obj"/>
      </geometry>
    </collision>
  </link>
  <link name="lb_hip">
    <inertial>
      <origin xyz="0.0 0.0 0.0" rpy="0.0 0.0 0.0"/>
      <mass value="0.03004188265707728"/>
      <inertia ixx="2.9411473822971713e-05" ixy="1.2390582935298588e-06" ixz="1.3485851429965568e-10" iyy="5.0921318299200916e-05" iyz="-4.874777577245254e-11" izz="3.3715613520396384e-05"/>
    </inertial>
    <visual>
      <origin xyz="0.0 0.0 0.0" rpy="0.0 0.0 0.0"/>
      <geometry>
        <mesh filename="mesh/lb_hip.obj"/>
      </geometry>
      <material name="#ffffffff">
        <color rgba="1 1 1 1"/>
      </material>
    </visual>
    <collision>
      <origin xyz="0.0 0.0 0.0" rpy="0.0 0.0 0.0"/>
      <geometry>
        <mesh filename="mesh/lb_hip.obj"/>
      </geometry>
    </collision>
  </link>
  <link name="lb_m2">
    <inertial>
      <origin xyz="0.0 0.0 0.0" rpy="0.0 0.0 0.0"/>
      <mass value="0.03257455734158853"/>
      <inertia ixx="2.30860579309019e-05" ixy="-3.017172025783328e-10" ixz="6.14426220694766e-12" iyy="1.592727621325853e-05" iyz="-3.5801482125832484e-12" izz="1.592782531081773e-05"/>
    </inertial>
    <visual>
      <origin xyz="0.0 0.0 0.0" rpy="0.0 0.0 0.0"/>
      <geometry>
        <mesh filename="mesh/lb_m2.obj"/>
      </geometry>
      <material name="#ffffffff">
        <color rgba="1 1 1 1"/>
      </material>
    </visual>
    <collision>
      <origin xyz="0.0 0.0 0.0" rpy="0.0 0.0 0.0"/>
      <geometry>
        <mesh filename="mesh/lb_m2.obj"/>
      </geometry>
    </collision>
  </link>
  <link name="lb_tc">
    <inertial>
      <origin xyz="0.0 0.0 0.0" rpy="0.0 0.0 0.0"/>
      <mass value="0.005815865339497284"/>
      <inertia ixx="3.943871513347597e-06" ixy="-8.801990579595257e-11" ixz="-1.05332769726045e-06" iyy="4.060625301326516e-06" iyz="-2.6869372681749636e-11" izz="2.7234200311580347e-06"/>
    </inertial>
    <visual>
      <origin xyz="0.0 0.0 0.0" rpy="0.0 0.0 0.0"/>
      <geometry>
        <mesh filename="mesh/lb_tc.obj"/>
      </geometry>
      <material name="#ffffffff">
        <color rgba="1 1 1 1"/>
      </material>
    </visual>
    <collision>
      <origin xyz="0.0 0.0 0.0" rpy="0.0 0.0 0.0"/>
      <geometry>
        <mesh filename="mesh/lb_tc.obj"/>
      </geometry>
    </collision>
  </link>
  <link name="lb_thigh">
    <inertial>
      <origin xyz="0.0 0.0 0.0" rpy="0.0 0.0 0.0"/>
      <mass value="0.056003570757274454"/>
      <inertia ixx="0.00012076904408054403" ixy="2.2435575170364517e-10" ixz="-9.893221423453491e-06" iyy="0.00010674518099689661" iyz="4.6333101083951687e-10" izz="4.647764726325559e-05"/>
    </inertial>
    <visual>
      <origin xyz="0.0 0.0 0.0" rpy="0.0 0.0 0.0"/>
      <geometry>
        <mesh filename="mesh/lb_thigh.obj"/>
      </geometry>
      <material name="#ffffffff">
        <color rgba="1 1 1 1"/>
      </material>
    </visual>
    <collision>
      <origin xyz="0.0 0.0 0.0" rpy="0.0 0.0 0.0"/>
      <geometry>
        <mesh filename="mesh/lb_thigh.obj"/>
      </geometry>
    </collision>
  </link>
  <link name="lb_m3">
    <inertial>
      <origin xyz="0.0 0.0 0.0" rpy="0.0 0.0 0.0"/>
      <mass value="0.03257455734158853"/>
      <inertia ixx="2.30860579309019e-05" ixy="-3.017172025783328e-10" ixz="6.14426220694766e-12" iyy="1.592727621325853e-05" iyz="-3.5801482125832484e-12" izz="1.592782531081773e-05"/>
    </inertial>
    <visual>
      <origin xyz="0.0 0.0 0.0" rpy="0.0 0.0 0.0"/>
      <geometry>
        <mesh filename="mesh/lb_m3.obj"/>
      </geometry>
      <material name="#ffffffff">
        <color rgba="1 1 1 1"/>
      </material>
    </visual>
    <collision>
      <origin xyz="0.0 0.0 0.0" rpy="0.0 0.0 0.0"/>
      <geometry>
        <mesh filename="mesh/lb_m3.obj"/>
      </geometry>
    </collision>
  </link>
  <link name="lb_sc">
    <inertial>
      <origin xyz="0.0 0.0 0.0" rpy="0.0 0.0 0.0"/>
      <mass value="0.004450137728878035"/>
      <inertia ixx="2.9370575854857886e-06" ixy="-3.0650854109537005e-13" ixz="-6.649014992215239e-07" iyy="2.9183966735791384e-06" iyz="-1.7493508853044012e-11" izz="1.3045258593510258e-06"/>
    </inertial>
    <visual>
      <origin xyz="0.0 0.0 0.0" rpy="0.0 0.0 0.0"/>
      <geometry>
        <mesh filename="mesh/lb_sc.obj"/>
      </geometry>
      <material name="#ffffffff">
        <color rgba="1 1 1 1"/>
      </material>
    </visual>
    <collision>
      <origin xyz="0.0 0.0 0.0" rpy="0.0 0.0 0.0"/>
      <geometry>
        <mesh filename="mesh/lb_sc.obj"/>
      </geometry>
    </collision>
  </link>
  <link name="lb_shank">
    <inertial>
      <origin xyz="0.0 0.0 0.0" rpy="0.0 0.0 0.0"/>
      <mass value="0.12611282906621582"/>
      <inertia ixx="0.00027463631018358843" ixy="-2.785808356684213e-09" ixz="-1.5907796894148622e-10" iyy="0.00021072435623559495" iyz="4.75253712033445e-05" izz="0.00018815447142988396"/>
    </inertial>
    <visual>
      <origin xyz="0.0 0.0 0.0" rpy="0.0 0.0 0.0"/>
      <geometry>
        <mesh filename="mesh/lb_shank.obj"/>
      </geometry>
      <material name="#ffffffff">
        <color rgba="1 1 1 1"/>
      </material>
    </visual>
    <collision>
      <origin xyz="0.0 0.0 0.0" rpy="0.0 0.0 0.0"/>
      <geometry>
        <mesh filename="mesh/lb_shank.obj"/>
      </geometry>
    </collision>
  </link>
  <link name="rb_m1">
    <inertial>
      <origin xyz="0.0 0.0 0.0" rpy="0.0 0.0 0.0"/>
      <mass value="0.03257455734158853"/>
      <inertia ixx="2.30860579309019e-05" ixy="-3.017172025783328e-10" ixz="6.14426220694766e-12" iyy="1.592727621325853e-05" iyz="-3.5801482125832484e-12" izz="1.592782531081773e-05"/>
    </inertial>
    <visual>
      <origin xyz="0.0 0.0 0.0" rpy="0.0 0.0 0.0"/>
      <geometry>
        <mesh filename="mesh/rb_m1.obj"/>
      </geometry>
      <material name="#ffffffff">
        <color rgba="1 1 1 1"/>
      </material>
    </visual>
    <collision>
      <origin xyz="0.0 0.0 0.0" rpy="0.0 0.0 0.0"/>
      <geometry>
        <mesh filename="mesh/rb_m1.obj"/>
      </geometry>
    </collision>
  </link>
  <link name="rb_hip">
    <inertial>
      <origin xyz="0.0 0.0 0.0" rpy="0.0 0.0 0.0"/>
      <mass value="0.03004188265707728"/>
      <inertia ixx="2.9411473822971713e-05" ixy="1.2390582935298588e-06" ixz="1.3485851429965568e-10" iyy="5.0921318299200916e-05" iyz="-4.874777577245254e-11" izz="3.3715613520396384e-05"/>
    </inertial>
    <visual>
      <origin xyz="0.0 0.0 0.0" rpy="0.0 0.0 0.0"/>
      <geometry>
        <mesh filename="mesh/rb_hip.obj"/>
      </geometry>
      <material name="#ffffffff">
        <color rgba="1 1 1 1"/>
      </material>
    </visual>
    <collision>
      <origin xyz="0.0 0.0 0.0" rpy="0.0 0.0 0.0"/>
      <geometry>
        <mesh filename="mesh/rb_hip.obj"/>
      </geometry>
    </collision>
  </link>
  <link name="rb_m2">
    <inertial>
      <origin xyz="0.0 0.0 0.0" rpy="0.0 0.0 0.0"/>
      <mass value="0.03257455734158853"/>
      <inertia ixx="2.30860579309019e-05" ixy="-3.017172025783328e-10" ixz="6.14426220694766e-12" iyy="1.592727621325853e-05" iyz="-3.5801482125832484e-12" izz="1.592782531081773e-05"/>
    </inertial>
    <visual>
      <origin xyz="0.0 0.0 0.0" rpy="0.0 0.0 0.0"/>
      <geometry>
        <mesh filename="mesh/rb_m2.obj"/>
      </geometry>
      <material name="#ffffffff">
        <color rgba="1 1 1 1"/>
      </material>
    </visual>
    <collision>
      <origin xyz="0.0 0.0 0.0" rpy="0.0 0.0 0.0"/>
      <geometry>
        <mesh filename="mesh/rb_m2.obj"/>
      </geometry>
    </collision>
  </link>
  <link name="rb_tc">
    <inertial>
      <origin xyz="0.0 0.0 0.0" rpy="0.0 0.0 0.0"/>
      <mass value="0.005815865339497284"/>
      <inertia ixx="3.943871513347597e-06" ixy="-8.801990579595257e-11" ixz="-1.05332769726045e-06" iyy="4.060625301326516e-06" iyz="-2.6869372681749636e-11" izz="2.7234200311580347e-06"/>
    </inertial>
    <visual>
      <origin xyz="0.0 0.0 0.0" rpy="0.0 0.0 0.0"/>
      <geometry>
        <mesh filename="mesh/rb_tc.obj"/>
      </geometry>
      <material name="#ffffffff">
        <color rgba="1 1 1 1"/>
      </material>
    </visual>
    <collision>
      <origin xyz="0.0 0.0 0.0" rpy="0.0 0.0 0.0"/>
      <geometry>
        <mesh filename="mesh/rb_tc.obj"/>
      </geometry>
    </collision>
  </link>
  <link name="rb_thigh">
    <inertial>
      <origin xyz="0.0 0.0 0.0" rpy="0.0 0.0 0.0"/>
      <mass value="0.056003570757274454"/>
      <inertia ixx="0.00012076904408054403" ixy="2.2435575170364517e-10" ixz="-9.893221423453491e-06" iyy="0.00010674518099689661" iyz="4.6333101083951687e-10" izz="4.647764726325559e-05"/>
    </inertial>
    <visual>
      <origin xyz="0.0 0.0 0.0" rpy="0.0 0.0 0.0"/>
      <geometry>
        <mesh filename="mesh/rb_thigh.obj"/>
      </geometry>
      <material name="#ffffffff">
        <color rgba="1 1 1 1"/>
      </material>
    </visual>
    <collision>
      <origin xyz="0.0 0.0 0.0" rpy="0.0 0.0 0.0"/>
      <geometry>
        <mesh filename="mesh/rb_thigh.obj"/>
      </geometry>
    </collision>
  </link>
  <link name="rb_m3">
    <inertial>
      <origin xyz="0.0 0.0 0.0" rpy="0.0 0.0 0.0"/>
      <mass value="0.03257455734158853"/>
      <inertia ixx="2.30860579309019e-05" ixy="-3.017172025783328e-10" ixz="6.14426220694766e-12" iyy="1.592727621325853e-05" iyz="-3.5801482125832484e-12" izz="1.592782531081773e-05"/>
    </inertial>
    <visual>
      <origin xyz="0.0 0.0 0.0" rpy="0.0 0.0 0.0"/>
      <geometry>
        <mesh filename="mesh/rb_m3.obj"/>
      </geometry>
      <material name="#ffffffff">
        <color rgba="1 1 1 1"/>
      </material>
    </visual>
    <collision>
      <origin xyz="0.0 0.0 0.0" rpy="0.0 0.0 0.0"/>
      <geometry>
        <mesh filename="mesh/rb_m3.obj"/>
      </geometry>
    </collision>
  </link>
  <link name="rb_sc">
    <inertial>
      <origin xyz="0.0 0.0 0.0" rpy="0.0 0.0 0.0"/>
      <mass value="0.004450137728878035"/>
      <inertia ixx="2.9370575854857886e-06" ixy="-3.0650854109537005e-13" ixz="-6.649014992215239e-07" iyy="2.9183966735791384e-06" iyz="-1.7493508853044012e-11" izz="1.3045258593510258e-06"/>
    </inertial>
    <visual>
      <origin xyz="0.0 0.0 0.0" rpy="0.0 0.0 0.0"/>
      <geometry>
        <mesh filename="mesh/rb_sc.obj"/>
      </geometry>
      <material name="#ffffffff">
        <color rgba="1 1 1 1"/>
      </material>
    </visual>
    <collision>
      <origin xyz="0.0 0.0 0.0" rpy="0.0 0.0 0.0"/>
      <geometry>
        <mesh filename="mesh/rb_sc.obj"/>
      </geometry>
    </collision>
  </link>
  <link name="rb_shank">
    <inertial>
      <origin xyz="0.0 0.0 0.0" rpy="0.0 0.0 0.0"/>
      <mass value="0.12611282906621582"/>
      <inertia ixx="0.00027463631018358843" ixy="-2.785808356684213e-09" ixz="-1.5907796894148622e-10" iyy="0.00021072435623559495" iyz="4.75253712033445e-05" izz="0.00018815447142988396"/>
    </inertial>
    <visual>
      <origin xyz="0.0 0.0 0.0" rpy="0.0 0.0 0.0"/>
      <geometry>
        <mesh filename="mesh/rb_shank.obj"/>
      </geometry>
      <material name="#ffffffff">
        <color rgba="1 1 1 1"/>
      </material>
    </visual>
    <collision>
      <origin xyz="0.0 0.0 0.0" rpy="0.0 0.0 0.0"/>
      <geometry>
        <mesh filename="mesh/rb_shank.obj"/>
      </geometry>
    </collision>
  </link>
  <joint name="body,lf_m1" type="fixed">
    <origin xyz="0.09 0.0 0.07" rpy="-1.5707963267948963 0.0 0.0"/>
    <parent link="body"/>
    <child link="lf_m1"/>
    <axis xyz="1 0 0"/>
    <limit effort="11" velocity="51"/>
  </joint>
  <joint name="body,rf_m1" type="fixed">
    <origin xyz="-0.09 0.0 0.07" rpy="1.5707963267948963 2.220446049250313e-16 3.141592653589793"/>
    <parent link="body"/>
    <child link="rf_m1"/>
    <axis xyz="1 0 0"/>
    <limit effort="11" velocity="51"/>
  </joint>
  <joint name="body,lb_m1" type="fixed">
    <origin xyz="0.013000000000000001 0.0 -0.17500000000000002" rpy="-1.5707963267948963 0.0 0.0"/>
    <parent link="body"/>
    <child link="lb_m1"/>
    <axis xyz="1 0 0"/>
    <limit effort="11" velocity="51"/>
  </joint>
  <joint name="body,rb_m1" type="fixed">
    <origin xyz="-0.013000000000000001 0.0 -0.17500000000000002" rpy="1.5707963267948963 2.220446049250313e-16 3.141592653589793"/>
    <parent link="body"/>
    <child link="rb_m1"/>
    <axis xyz="1 0 0"/>
    <limit effort="11" velocity="51"/>
  </joint>
  <joint name="lf_m1,lf_hip" type="revolute">
    <origin xyz="0.029 0.0 0.0" rpy="3.141592653589793 0.0 0.0"/>
    <parent link="lf_m1"/>
    <child link="lf_hip"/>
    <axis xyz="1 0 0"/>
    <limit effort="11" velocity="51"/>
  </joint>
  <joint name="lf_hip,lf_m2" type="fixed">
    <origin xyz="0.051000000000000004 -0.0095 0.0" rpy="3.141592653589793 0.0 1.570796326794897"/>
    <parent link="lf_hip"/>
    <child link="lf_m2"/>
    <axis xyz="1 0 0"/>
    <limit effort="11" velocity="51"/>
  </joint>
  <joint name="lf_m2,lf_tc" type="revolute">
    <origin xyz="0.032 0.0 0.0" rpy="0.0 0.0 0.0"/>
    <parent link="lf_m2"/>
    <child link="lf_tc"/>
    <axis xyz="1 0 0"/>
    <limit effort="11" velocity="51"/>
  </joint>
  <joint name="lf_tc,lf_thigh" type="fixed">
    <origin xyz="-0.021500000000000002 0.0 -0.145" rpy="0.0 0.0 -1.5707963267948963"/>
    <parent link="lf_tc"/>
    <child link="lf_thigh"/>
    <axis xyz="1 0 0"/>
    <limit effort="11" velocity="51"/>
  </joint>
  <joint name="lf_thigh,lf_m3" type="fixed">
    <origin xyz="-0.012 0.0 0.0" rpy="0.0 0.0 0.0"/>
    <parent link="lf_thigh"/>
    <child link="lf_m3"/>
    <axis xyz="1 0 0"/>
    <limit effort="11" velocity="51"/>
  </joint>
  <joint name="lf_m3,lf_sc" type="revolute">
    <origin xyz="0.032 0.0 0.0" rpy="0.0 0.0 0.0"/>
    <parent link="lf_m3"/>
    <child link="lf_sc"/>
    <axis xyz="1 0 0"/>
    <limit effort="11" velocity="51"/>
  </joint>
  <joint name="lf_sc,lf_shank" type="fixed">
    <origin xyz="-0.02 0.0 -0.031" rpy="0.0 0.0 0.0"/>
    <parent link="lf_sc"/>
    <child link="lf_shank"/>
    <axis xyz="1 0 0"/>
    <limit effort="11" velocity="51"/>
  </joint>
  <joint name="rf_m1,rf_hip" type="revolute">
    <origin xyz="0.029 0.0 0.0" rpy="0.0 0.0 0.0"/>
    <parent link="rf_m1"/>
    <child link="rf_hip"/>
    <axis xyz="1 0 0"/>
    <limit effort="11" velocity="51"/>
  </joint>
  <joint name="rf_hip,rf_m2" type="fixed">
    <origin xyz="0.051000000000000004 -0.0095 0.0" rpy="0.0 0.0 1.5707963267948963"/>
    <parent link="rf_hip"/>
    <child link="rf_m2"/>
    <axis xyz="1 0 0"/>
    <limit effort="11" velocity="51"/>
  </joint>
  <joint name="rf_m2,rf_tc" type="revolute">
    <origin xyz="0.032 0.0 0.0" rpy="0.0 0.0 0.0"/>
    <parent link="rf_m2"/>
    <child link="rf_tc"/>
    <axis xyz="1 0 0"/>
    <limit effort="11" velocity="51"/>
  </joint>
  <joint name="rf_tc,rf_thigh" type="fixed">
    <origin xyz="-0.021500000000000002 0.0 -0.145" rpy="0.0 0.0 1.5707963267948963"/>
    <parent link="rf_tc"/>
    <child link="rf_thigh"/>
    <axis xyz="1 0 0"/>
    <limit effort="11" velocity="51"/>
  </joint>
  <joint name="rf_thigh,rf_m3" type="fixed">
    <origin xyz="-0.012 0.0 0.0" rpy="0.0 0.0 0.0"/>
    <parent link="rf_thigh"/>
    <child link="rf_m3"/>
    <axis xyz="1 0 0"/>
    <limit effort="11" velocity="51"/>
  </joint>
  <joint name="rf_m3,rf_sc" type="revolute">
    <origin xyz="0.032 0.0 0.0" rpy="0.0 0.0 0.0"/>
    <parent link="rf_m3"/>
    <child link="rf_sc"/>
    <axis xyz="1 0 0"/>
    <limit effort="11" velocity="51"/>
  </joint>
  <joint name="rf_sc,rf_shank" type="fixed">
    <origin xyz="-0.02 0.0 -0.031" rpy="0.0 0.0 0.0"/>
    <parent link="rf_sc"/>
    <child link="rf_shank"/>
    <axis xyz="1 0 0"/>
    <limit effort="11" velocity="51"/>
  </joint>
  <joint name="lb_m1,lb_hip" type="revolute">
    <origin xyz="0.032 0.0 0.0" rpy="0.0 0.0 0.0"/>
    <parent link="lb_m1"/>
    <child link="lb_hip"/>
    <axis xyz="1 0 0"/>
    <limit effort="11" velocity="51"/>
  </joint>
  <joint name="lb_hip,lb_m2" type="fixed">
    <origin xyz="0.051000000000000004 -0.0095 0.0" rpy="0.0 0.0 1.5707963267948963"/>
    <parent link="lb_hip"/>
    <child link="lb_m2"/>
    <axis xyz="1 0 0"/>
    <limit effort="11" velocity="51"/>
  </joint>
  <joint name="lb_m2,lb_tc" type="revolute">
    <origin xyz="0.032 0.0 0.0" rpy="0.0 0.0 0.0"/>
    <parent link="lb_m2"/>
    <child link="lb_tc"/>
    <axis xyz="1 0 0"/>
    <limit effort="11" velocity="51"/>
  </joint>
  <joint name="lb_tc,lb_thigh" type="fixed">
    <origin xyz="-0.021500000000000002 0.0 -0.145" rpy="0.0 0.0 1.5707963267948963"/>
    <parent link="lb_tc"/>
    <child link="lb_thigh"/>
    <axis xyz="1 0 0"/>
    <limit effort="11" velocity="51"/>
  </joint>
  <joint name="lb_thigh,lb_m3" type="fixed">
    <origin xyz="-0.012 0.0 0.0" rpy="0.0 0.0 0.0"/>
    <parent link="lb_thigh"/>
    <child link="lb_m3"/>
    <axis xyz="1 0 0"/>
    <limit effort="11" velocity="51"/>
  </joint>
  <joint name="lb_m3,lb_sc" type="revolute">
    <origin xyz="0.032 0.0 0.0" rpy="0.0 0.0 0.0"/>
    <parent link="lb_m3"/>
    <child link="lb_sc"/>
    <axis xyz="1 0 0"/>
    <limit effort="11" velocity="51"/>
  </joint>
  <joint name="lb_sc,lb_shank" type="fixed">
    <origin xyz="-0.02 0.0 0.0" rpy="0.0 0.0 0.0"/>
    <parent link="lb_sc"/>
    <child link="lb_shank"/>
    <axis xyz="1 0 0"/>
    <limit effort="11" velocity="51"/>
  </joint>
  <joint name="rb_m1,rb_hip" type="revolute">
    <origin xyz="0.032 0.0 0.0" rpy="3.141592653589793 0.0 0.0"/>
    <parent link="rb_m1"/>
    <child link="rb_hip"/>
    <axis xyz="1 0 0"/>
    <limit effort="11" velocity="51"/>
  </joint>
  <joint name="rb_hip,rb_m2" type="fixed">
    <origin xyz="0.051000000000000004 -0.0095 0.0" rpy="3.141592653589793 0.0 1.570796326794897"/>
    <parent link="rb_hip"/>
    <child link="rb_m2"/>
    <axis xyz="1 0 0"/>
    <limit effort="11" velocity="51"/>
  </joint>
  <joint name="rb_m2,rb_tc" type="revolute">
    <origin xyz="0.032 0.0 0.0" rpy="0.0 0.0 0.0"/>
    <parent link="rb_m2"/>
    <child link="rb_tc"/>
    <axis xyz="1 0 0"/>
    <limit effort="11" velocity="51"/>
  </joint>
  <joint name="rb_tc,rb_thigh" type="fixed">
    <origin xyz="-0.021500000000000002 0.0 -0.145" rpy="0.0 0.0 -1.5707963267948963"/>
    <parent link="rb_tc"/>
    <child link="rb_thigh"/>
    <axis xyz="1 0 0"/>
    <limit effort="11" velocity="51"/>
  </joint>
  <joint name="rb_thigh,rb_m3" type="fixed">
    <origin xyz="-0.012 0.0 0.0" rpy="0.0 0.0 0.0"/>
    <parent link="rb_thigh"/>
    <child link="rb_m3"/>
    <axis xyz="1 0 0"/>
    <limit effort="11" velocity="51"/>
  </joint>
  <joint name="rb_m3,rb_sc" type="revolute">
    <origin xyz="0.032 0.0 0.0" rpy="0.0 0.0 0.0"/>
    <parent link="rb_m3"/>
    <child link="rb_sc"/>
    <axis xyz="1 0 0"/>
    <limit effort="11" velocity="51"/>
  </joint>
  <joint name="rb_sc,rb_shank" type="fixed">
    <origin xyz="-0.02 0.0 0.0" rpy="0.0 0.0 3.141592653589793"/>
    <parent link="rb_sc"/>
    <child link="rb_shank"/>
    <axis xyz="1 0 0"/>
    <limit effort="11" velocity="51"/>
  </joint>
</robot>
