<?xml version="1.0" encoding="utf-8"?>
<!-- This URDF was automatically created by SolidWorks to URDF Exporter! Originally created by Stephen Brawner (brawner@gmail.com) 
     Commit Version: 1.5.1-0-g916b5db  Build Version: 1.5.7152.31018
     For more information, please see http://wiki.ros.org/sw_urdf_exporter -->
<robot
  name="0_degree">
  <link
    name="base_link">
    <inertial>
      <origin
        xyz="0 -1.6653E-16 1.7347E-18"
        rpy="0 0 0" />
      <mass
        value="2.803" />
      <inertia
        ixx="0.009830453"
        ixy="-6.6937E-19"
        ixz="-3.5461E-19"
        iyy="0.035244163"
        iyz="-2.2961E-18"
        izz="0.042800717" />
    </inertial>
    <visual>
      <origin
        xyz="0 0 0"
        rpy="0 0 0" />
      <geometry>
        <mesh
          filename="package://0_degree/meshes/base_link.STL" />
      </geometry>
      <material
        name="">
        <color
          rgba="1 1 1 1" />
      </material>
    </visual>
    <collision>
      <origin
        xyz="0 0 0"
        rpy="0 0 0" />
      <geometry>
        <mesh
          filename="package://0_degree/meshes/base_link.STL" />
      </geometry>
    </collision>
  </link>
  <link
    name="left_fromt_link">
    <inertial>
      <origin
        xyz="-2.4843E-07 0.047047 -0.035562"
        rpy="0 0 0" />
      <mass
        value="0.0769" />
      <inertia
        ixx="0.000164541"
        ixy="6.3951E-10"
        ixz="5.8383E-10"
        iyy="0.000045093"
        iyz="1.7464E-05"
        izz="0.000162052" />
    </inertial>
    <visual>
      <origin
        xyz="0 0 0"
        rpy="0 0 0" />
      <geometry>
        <mesh
          filename="package://0_degree/meshes/left_fromt_link.STL" />
      </geometry>
      <material
        name="">
        <color
          rgba="1 1 1 1" />
      </material>
    </visual>
    <collision>
      <origin
        xyz="0 0 0"
        rpy="0 0 0" />
      <geometry>
        <mesh
          filename="package://0_degree/meshes/left_fromt_link.STL" />
      </geometry>
    </collision>
  </link>
  <joint
    name="left_front_leg"
    type="continuous">
    <origin
      xyz="0.13 0.103 0"
      rpy="1.5708 1.5708 0" />
    <parent
      link="base_link" />
    <child
      link="left_fromt_link" />
    <axis
      xyz="0 0 -1" />
    <limit
      effort="5"
      velocity="487" />
  </joint>
  <link
    name="right_front_link">
    <inertial>
      <origin
        xyz="2.4843E-07 0.047047 0.035562"
        rpy="0 0 0" />
      <mass
        value="0.0769" />
      <inertia
        ixx="0.000164541"
        ixy="-6.3951E-10"
        ixz="5.8383E-10"
        iyy="0.000045093"
        iyz="-1.7464E-05"
        izz="0.000162052" />
    </inertial>
    <visual>
      <origin
        xyz="0 0 0"
        rpy="0 0 0" />
      <geometry>
        <mesh
          filename="package://0_degree/meshes/right_front_link.STL" />
      </geometry>
      <material
        name="">
        <color
          rgba="1 1 1 1" />
      </material>
    </visual>
    <collision>
      <origin
        xyz="0 0 0"
        rpy="0 0 0" />
      <geometry>
        <mesh
          filename="package://0_degree/meshes/right_front_link.STL" />
      </geometry>
    </collision>
  </link>
  <joint
    name="right_front_leg"
    type="continuous">
    <origin
      xyz="0.13 -0.103 0"
      rpy="1.5708 1.5708 0" />
    <parent
      link="base_link" />
    <child
      link="right_front_link" />
    <axis
      xyz="0 0 1" />
    <limit
      effort="5"
      velocity="487" />
  </joint>
  <link
    name="right_back_link">
    <inertial>
      <origin
        xyz="2.4843E-07 0.047047 0.035562"
        rpy="0 0 0" />
      <mass
        value="0.0769" />
      <inertia
        ixx="0.000164541"
        ixy="-6.3951E-10"
        ixz="5.8383E-10"
        iyy="0.000045093"
        iyz="-1.7464E-05"
        izz="0.000162052" />
    </inertial>
    <visual>
      <origin
        xyz="0 0 0"
        rpy="0 0 0" />
      <geometry>
        <mesh
          filename="package://0_degree/meshes/right_back_link.STL" />
      </geometry>
      <material
        name="">
        <color
          rgba="1 1 1 1" />
      </material>
    </visual>
    <collision>
      <origin
        xyz="0 0 0"
        rpy="0 0 0" />
      <geometry>
        <mesh
          filename="package://0_degree/meshes/right_back_link.STL" />
      </geometry>
    </collision>
  </link>
  <joint
    name="right_back_leg"
    type="continuous">
    <origin
      xyz="-0.13 -0.103 0"
      rpy="1.5708 1.5708 0" />
    <parent
      link="base_link" />
    <child
      link="right_back_link" />
    <axis
      xyz="0 0 1" />
    <limit
      effort="5"
      velocity="487" />
  </joint>
  <link
    name="left_back_link">
    <inertial>
      <origin
        xyz="-2.4843E-07 0.047047 -0.035562"
        rpy="0 0 0" />
      <mass
        value="0.0769" />
      <inertia
        ixx="0.000164541"
        ixy="6.3951E-10"
        ixz="5.8383E-10"
        iyy="0.000045093"
        iyz="1.7464E-05"
        izz="0.000162052" />
    </inertial>
    <visual>
      <origin
        xyz="0 0 0"
        rpy="0 0 0" />
      <geometry>
        <mesh
          filename="package://0_degree/meshes/left_back_link.STL" />
      </geometry>
      <material
        name="">
        <color
          rgba="1 1 1 1" />
      </material>
    </visual>
    <collision>
      <origin
        xyz="0 0 0"
        rpy="0 0 0" />
      <geometry>
        <mesh
          filename="package://0_degree/meshes/left_back_link.STL" />
      </geometry>
    </collision>
  </link>
  <joint
    name="left_back_leg"
    type="continuous">
    <origin
      xyz="-0.13 0.103 0"
      rpy="1.5708 1.5708 0" />
    <parent
      link="base_link" />
    <child
      link="left_back_link" />
    <axis
      xyz="0 0 -1" />
    <limit
      effort="5"
      velocity="487" />
  </joint>
</robot>