<?xml version="1.0" encoding="utf-8"?>
<!-- This URDF was automatically created by SolidWorks to URDF Exporter! Originally created by Stephen Brawner (brawner@gmail.com) 
     Commit Version: 1.5.1-0-g916b5db  Build Version: 1.5.7152.31018
     For more information, please see http://wiki.ros.org/sw_urdf_exporter -->
<robot
  name="26_degree">
  <link
    name="base_link">
    <inertial>
      <origin
        xyz="-6.9389E-18 8.0095E-08 3.4694E-18"
        rpy="0 0 0" />
      <mass
        value="2.803" />
      <inertia
        ixx="0.009390267"
        ixy="-3.3749E-19"
        ixz="-9.2678E-09"
        iyy="0.045536293"
        iyz="2.3182E-18"
        izz="0.052545964" />
    </inertial>
    <visual>
      <origin
        xyz="0 0 0"
        rpy="0 0 0" />
      <geometry>
        <mesh
          filename="package://26_degree/meshes/base_link.STL" />
      </geometry>
      <material
        name="">
        <color
          rgba="1 1 1 1" />
      </material>
    </visual>
    <collision>
      <origin
        xyz="0 0 0"
        rpy="0 0 0" />
      <geometry>
        <mesh
          filename="package://26_degree/meshes/base_link.STL" />
      </geometry>
    </collision>
  </link>
  <link
    name="left_fromt_link">
    <inertial>
      <origin
        xyz="-8.5031E-08 0.081625 -0.00080805"
        rpy="0 0 0" />
      <mass
        value="0.0967" />
      <inertia
        ixx="0.00042516"
        ixy="-8.7164E-11"
        ixz="1.034E-09"
        iyy="0.00010276"
        iyz="-0.000129125"
        izz="0.000372399" />
    </inertial>
    <visual>
      <origin
        xyz="0 0 0"
        rpy="0 0 0" />
      <geometry>
        <mesh
          filename="package://26_degree/meshes/left_fromt_link.STL" />
      </geometry>
      <material
        name="">
        <color
          rgba="1 1 1 1" />
      </material>
    </visual>
    <collision>
      <origin
        xyz="0 0 0"
        rpy="0 0 0" />
      <geometry>
        <mesh
          filename="package://26_degree/meshes/left_fromt_link.STL" />
      </geometry>
    </collision>
  </link>
  <joint
    name="left_front_leg"
    type="continuous">
    <origin
      xyz="0.17515 0.092576 0"
      rpy="1.5708 1.5708 0" />
    <parent
      link="base_link" />
    <child
      link="left_fromt_link" />
    <axis
      xyz="0 0.43837 -0.89879" />
    <limit
      effort="5"
      velocity="487" />
  </joint>
  <link
    name="right_front_link">
    <inertial>
      <origin
        xyz="8.5031E-08 0.081625 0.00080805"
        rpy="0 0 0" />
      <mass
        value="0.0967" />
      <inertia
        ixx="0.00042516"
        ixy="8.7164E-11"
        ixz="1.034E-09"
        iyy="0.000102706"
        iyz="0.000129125"
        izz="0.000372399" />
    </inertial>
    <visual>
      <origin
        xyz="0 0 0"
        rpy="0 0 0" />
      <geometry>
        <mesh
          filename="package://26_degree/meshes/right_front_link.STL" />
      </geometry>
      <material
        name="">
        <color
          rgba="1 1 1 1" />
      </material>
    </visual>
    <collision>
      <origin
        xyz="0 0 0"
        rpy="0 0 0" />
      <geometry>
        <mesh
          filename="package://26_degree/meshes/right_front_link.STL" />
      </geometry>
    </collision>
  </link>
  <joint
    name="right_front_leg"
    type="continuous">
    <origin
      xyz="0.17515 -0.092576 0"
      rpy="1.5708 1.5708 0" />
    <parent
      link="base_link" />
    <child
      link="right_front_link" />
    <axis
      xyz="0 0.43837 0.89879" />
    <limit
      effort="5"
      velocity="487" />
  </joint>
  <link
    name="right_back_link">
    <inertial>
      <origin
        xyz="7.1751E-08 0.07301 0.036508"
        rpy="0 0 0" />
      <mass
        value="0.0967" />
      <inertia
        ixx="0.00042516"
        ixy="-3.2015E-10"
        ixz="1.3308E-10"
        iyy="0.000052824"
        iyz="-0.000026741"
        izz="0.000422335" />
    </inertial>
    <visual>
      <origin
        xyz="0 0 0"
        rpy="0 0 0" />
      <geometry>
        <mesh
          filename="package://26_degree/meshes/right_back_link.STL" />
      </geometry>
      <material
        name="">
        <color
          rgba="1 1 1 1" />
      </material>
    </visual>
    <collision>
      <origin
        xyz="0 0 0"
        rpy="0 0 0" />
      <geometry>
        <mesh
          filename="package://26_degree/meshes/right_back_link.STL" />
      </geometry>
    </collision>
  </link>
  <joint
    name="right_back_leg"
    type="continuous">
    <origin
      xyz="-0.17515 -0.092576 0"
      rpy="2.0246 1.5708 0" />
    <parent
      link="base_link" />
    <child
      link="right_back_link" />
    <axis
      xyz="0 0 1" />
    <limit
      effort="5"
      velocity="487" />
  </joint>
  <link
    name="left_back_link">
    <inertial>
      <origin
        xyz="-7.1751E-08 0.049617 -0.064819"
        rpy="0 0 0" />
      <mass
        value="0.0967" />
      <inertia
        ixx="0.00042516"
        ixy="3.4609E-10"
        ixz="-2.0733E-11"
        iyy="0.000144906"
        iyz="0.00162053"
        izz="0.000330254" />
    </inertial>
    <visual>
      <origin
        xyz="0 0 0"
        rpy="0 0 0" />
      <geometry>
        <mesh
          filename="package://26_degree/meshes/left_back_link.STL" />
      </geometry>
      <material
        name="">
        <color
          rgba="1 1 1 1" />
      </material>
    </visual>
    <collision>
      <origin
        xyz="0 0 0"
        rpy="0 0 0" />
      <geometry>
        <mesh
          filename="package://26_degree/meshes/left_back_link.STL" />
      </geometry>
    </collision>
  </link>
  <joint
    name="left_back_leg"
    type="continuous">
    <origin
      xyz="-0.17515 0.092576 0"
      rpy="1.5708 1.5708 0" />
    <parent
      link="base_link" />
    <child
      link="left_back_link" />
    <axis
      xyz="0 -0.43837 -0.89879" />
    <limit
      effort="5"
      velocity="487" />
  </joint>
</robot>