<?xml version="1.0" encoding="utf-8"?>
<!-- This URDF was automatically created by SolidWorks to URDF Exporter! Originally created by Stephen Brawner (brawner@gmail.com) 
     Commit Version: 1.5.1-0-g916b5db  Build Version: 1.5.7152.31018
     For more information, please see http://wiki.ros.org/sw_urdf_exporter -->
<robot
  name="9_degree">
  <link
    name="base_link">
    <inertial>
      <origin
        xyz="3.4694E-17 3.3926E-08 5.2042E-18"
        rpy="0 0 0" />
      <mass
        value="2.803" />
      <inertia
        ixx="0.010202845"
        ixy="4.6705E-19"
        ixz="-8.6671E-11"
        iyy="0.038222369"
        iyz="5.1377E-18"
        izz="0.046063310" />
    </inertial>
    <visual>
      <origin
        xyz="0 0 0"
        rpy="0 0 0" />
      <geometry>
        <mesh
          filename="package://9_degree/meshes/base_link.STL" />
      </geometry>
      <material
        name="">
        <color
          rgba="1 1 1 1" />
      </material>
    </visual>
    <collision>
      <origin
        xyz="0 0 0"
        rpy="0 0 0" />
      <geometry>
        <mesh
          filename="package://9_degree/meshes/base_link.STL" />
      </geometry>
    </collision>
  </link>
  <link
    name="left_fromt_link">
    <inertial>
      <origin
        xyz="-2.5031E-08 0.06054 -0.026821"
        rpy="0 0 0" />
      <mass
        value="0.0842" />
      <inertia
        ixx="0.000230004"
        ixy="5.1757E-10"
        ixz="7.2828E-10"
        iyy="0.000046294"
        iyz="-0.8156E-05"
        izz="0.000229331" />
    </inertial>
    <visual>
      <origin
        xyz="0 0 0"
        rpy="0 0 0" />
      <geometry>
        <mesh
          filename="package://9_degree/meshes/left_fromt_link.STL" />
      </geometry>
      <material
        name="">
        <color
          rgba="1 1 1 1" />
      </material>
    </visual>
    <collision>
      <origin
        xyz="0 0 0"
        rpy="0 0 0" />
      <geometry>
        <mesh
          filename="package://9_degree/meshes/left_fromt_link.STL" />
      </geometry>
    </collision>
  </link>
  <joint
    name="left_front_leg"
    type="continuous">
    <origin
      xyz="0.14611 0.10173 0"
      rpy="1.5708 1.5708 0" />
    <parent
      link="base_link" />
    <child
      link="left_fromt_link" />
    <axis
      xyz="0 0.15643 -0.98769" />
    <limit
      effort="5"
      velocity="487" />
  </joint>
  <link
    name="right_front_link">
    <inertial>
      <origin
        xyz="2.5031E-08 0.06054 0.026821"
        rpy="0 0 0" />
      <mass
        value="0.0842" />
      <inertia
        ixx="0.000230004"
        ixy="-5.1757E-10"
        ixz="7.2828E-10"
        iyy="0.000046294"
        iyz="0.8156E-05"
        izz="0.000229331" />
    </inertial>
    <visual>
      <origin
        xyz="0 0 0"
        rpy="0 0 0" />
      <geometry>
        <mesh
          filename="package://9_degree/meshes/right_front_link.STL" />
      </geometry>
      <material
        name="">
        <color
          rgba="1 1 1 1" />
      </material>
    </visual>
    <collision>
      <origin
        xyz="0 0 0"
        rpy="0 0 0" />
      <geometry>
        <mesh
          filename="package://9_degree/meshes/right_front_link.STL" />
      </geometry>
    </collision>
  </link>
  <joint
    name="right_front_leg"
    type="continuous">
    <origin
      xyz="0.14611 -0.10173 0"
      rpy="1.5708 1.5708 0" />
    <parent
      link="base_link" />
    <child
      link="right_front_link" />
    <axis
      xyz="0 0.15643 0.98769" />
    <limit
      effort="5"
      velocity="487" />
  </joint>
  <link
    name="right_back_link">
    <inertial>
      <origin
        xyz="5.7577E-09 0.055599 0.035961"
        rpy="0 0 0" />
      <mass
        value="0.0842" />
      <inertia
        ixx="0.000230004"
        ixy="-5.199E-10"
        ixz="5.8809E-10"
        iyy="0.000048253"
        iyz="-2.0524E-05"
        izz="0.000227372" />
    </inertial>
    <visual>
      <origin
        xyz="0 0 0"
        rpy="0 0 0" />
      <geometry>
        <mesh
          filename="package://9_degree/meshes/right_back_link.STL" />
      </geometry>
      <material
        name="">
        <color
          rgba="1 1 1 1" />
      </material>
    </visual>
    <collision>
      <origin
        xyz="0 0 0"
        rpy="0 0 0" />
      <geometry>
        <mesh
          filename="package://9_degree/meshes/right_back_link.STL" />
      </geometry>
    </collision>
  </link>
  <joint
    name="right_back_leg"
    type="continuous">
    <origin
      xyz="-0.14611 -0.10173 0"
      rpy="1.7279 1.5708 0" />
    <parent
      link="base_link" />
    <child
      link="right_back_link" />
    <axis
      xyz="0 0 1" />
    <limit
      effort="5"
      velocity="487" />
  </joint>
  <link
    name="left_back_link">
    <inertial>
      <origin
        xyz="-5.7577E-09 0.049289 -0.044216"
        rpy="0 0 0" />
      <mass
        value="0.0842" />
      <inertia
        ixx="0.000230004"
        ixy="6.055E-10"
        ixz="4.9952E-10"
        iyy="0.000058979"
        iyz="0.00047195"
        izz="0.000216646" />
    </inertial>
    <visual>
      <origin
        xyz="0 0 0"
        rpy="0 0 0" />
      <geometry>
        <mesh
          filename="package://9_degree/meshes/left_back_link.STL" />
      </geometry>
      <material
        name="">
        <color
          rgba="1 1 1 1" />
      </material>
    </visual>
    <collision>
      <origin
        xyz="0 0 0"
        rpy="0 0 0" />
      <geometry>
        <mesh
          filename="package://9_degree/meshes/left_back_link.STL" />
      </geometry>
    </collision>
  </link>
  <joint
    name="left_back_leg"
    type="continuous">
    <origin
      xyz="-0.14611 0.10173 0"
      rpy="1.5708 1.5708 0" />
    <parent
      link="base_link" />
    <child
      link="left_back_link" />
    <axis
      xyz="0 -0.15643 -0.98769" />
    <limit
      effort="5"
      velocity="487" />
  </joint>
</robot>