<?xml version="1.0" encoding="utf-8"?>
<!-- This URDF was automatically created by SolidWorks to URDF Exporter! Originally created by Stephen Brawner (brawner@gmail.com) 
     Commit Version: 1.5.1-0-g916b5db  Build Version: 1.5.7152.31018
     For more information, please see http://wiki.ros.org/sw_urdf_exporter -->
<robot
  name="11_degree">
  <link
    name="base_link">
    <inertial>
      <origin
        xyz="3.4694E-17 2.7487E-08 -1.7347E-18"
        rpy="0 0 0" />
      <mass
        value="2.942" />
      <inertia
        ixx="0.0101423"
        ixy="2.3525E-18"
        ixz="-1.5276E-10"
        iyy="0.0415884"
        iyz="2.19E-18"
        izz="0.0493376" />
    </inertial>
    <visual>
      <origin
        xyz="0 0 0"
        rpy="0 0 0" />
      <geometry>
        <mesh
          filename="package://11_degree/meshes/base_link.STL" />
      </geometry>
      <material
        name="">
        <color
          rgba="1 1 1 1" />
      </material>
    </visual>
    <collision>
      <origin
        xyz="0 0 0"
        rpy="0 0 0" />
      <geometry>
        <mesh
          filename="package://11_degree/meshes/base_link.STL" />
      </geometry>
    </collision>
  </link>
  <link
    name="left_front_link">
    <inertial>
      <origin
        xyz="-1.6225E-09 0.062657 -0.024505"
        rpy="0 0 0" />
      <mass
        value="0.092" />
      <inertia
        ixx="0.0002604"
        ixy="6.3745E-10"
        ixz="9.3337E-10"
        iyy="0.0000516"
        iyz="-1.74E-05"
        izz="0.0002586" />
    </inertial>
    <visual>
      <origin
        xyz="0 0 0"
        rpy="0 0 0" />
      <geometry>
        <mesh
          filename="package://11_degree/meshes/left_front_link.STL" />
      </geometry>
      <material
        name="">
        <color
          rgba="1 1 1 1" />
      </material>
    </visual>
    <collision>
      <origin
        xyz="0 0 0"
        rpy="0 0 0" />
      <geometry>
        <mesh
          filename="package://11_degree/meshes/left_front_link.STL" />
      </geometry>
    </collision>
  </link>
  <joint
    name="left_front_leg"
    type="continuous">
    <origin
      xyz="0.14965 0.10111 0"
      rpy="1.5708 1.5708 0" />
    <parent
      link="base_link" />
    <child
      link="left_front_link" />
    <axis
      xyz="0 0.19081 -0.98163" />
    <limit
      effort="5"
      velocity="487" />
  </joint>
  <link
    name="right_front_link">
    <inertial>
      <origin
        xyz="1.6225E-09 0.062657 0.024505"
        rpy="0 0 0" />
      <mass
        value="0.092" />
      <inertia
        ixx="0.0002604"
        ixy="-6.3745E-10"
        ixz="9.3337E-10"
        iyy="0.0000516"
        iyz="1.74E-05"
        izz="0.0002586" />
    </inertial>
    <visual>
      <origin
        xyz="0 0 0"
        rpy="0 0 0" />
      <geometry>
        <mesh
          filename="package://11_degree/meshes/right_front_link.STL" />
      </geometry>
      <material
        name="">
        <color
          rgba="1 1 1 1" />
      </material>
    </visual>
    <collision>
      <origin
        xyz="0 0 0"
        rpy="0 0 0" />
      <geometry>
        <mesh
          filename="package://11_degree/meshes/right_front_link.STL" />
      </geometry>
    </collision>
  </link>
  <joint
    name="right_front_leg"
    type="continuous">
    <origin
      xyz="0.14965 -0.10111 0"
      rpy="1.5708 1.5708 0" />
    <parent
      link="base_link" />
    <child
      link="right_front_link" />
    <axis
      xyz="0 0.19081 0.98163" />
    <limit
      effort="5"
      velocity="487" />
  </joint>
  <link
    name="right_back_link">
    <inertial>
      <origin
        xyz="3.1708E-09 0.05683 0.036011"
        rpy="0 0 0" />
      <mass
        value="0.092" />
      <inertia
        ixx="0.0002604"
        ixy="-5.3274E-10"
        ixz="5.8484E-10"
        iyy="0.0000526"
        iyz="-2.27E-05"
        izz="0.0002575" />
    </inertial>
    <visual>
      <origin
        xyz="0 0 0"
        rpy="0 0 0" />
      <geometry>
        <mesh
          filename="package://11_degree/meshes/right_back_link.STL" />
      </geometry>
      <material
        name="">
        <color
          rgba="1 1 1 1" />
      </material>
    </visual>
    <collision>
      <origin
        xyz="0 0 0"
        rpy="0 0 0" />
      <geometry>
        <mesh
          filename="package://11_degree/meshes/right_back_link.STL" />
      </geometry>
    </collision>
  </link>
  <joint
    name="right_back_leg"
    type="continuous">
    <origin
      xyz="-0.14965 -0.10111 0"
      rpy="1.7628 1.5708 0" />
    <parent
      link="base_link" />
    <child
      link="right_back_link" />
    <axis
      xyz="0 0 1" />
    <limit
      effort="5"
      velocity="487" />
  </joint>
  <link
    name="left_back_link">
    <inertial>
      <origin
        xyz="-3.1708E-09 0.048915 -0.046193"
        rpy="0 0 0" />
      <mass
        value="0.092" />
      <inertia
        ixx="0.0002604"
        ixy="6.3454E-10"
        ixz="4.7245E-10"
        iyy="0.0000686"
        iyz="0.0000594"
        izz="0.0002416" />
    </inertial>
    <visual>
      <origin
        xyz="0 0 0"
        rpy="0 0 0" />
      <geometry>
        <mesh
          filename="package://11_degree/meshes/left_back_link.STL" />
      </geometry>
      <material
        name="">
        <color
          rgba="1 1 1 1" />
      </material>
    </visual>
    <collision>
      <origin
        xyz="0 0 0"
        rpy="0 0 0" />
      <geometry>
        <mesh
          filename="package://11_degree/meshes/left_back_link.STL" />
      </geometry>
    </collision>
  </link>
  <joint
    name="left_back_leg"
    type="continuous">
    <origin
      xyz="-0.14965 0.10111 0"
      rpy="1.5708 1.5708 0" />
    <parent
      link="base_link" />
    <child
      link="left_back_link" />
    <axis
      xyz="0 -0.19081 -0.98163" />
    <limit
      effort="5"
      velocity="487" />
  </joint>
</robot>