<?xml version="1.0" encoding="utf-8"?>
<!-- This URDF was automatically created by SolidWorks to URDF Exporter! Originally created by Stephen Brawner (brawner@gmail.com) 
     Commit Version: 1.5.1-0-g916b5db  Build Version: 1.5.7152.31018
     For more information, please see http://wiki.ros.org/sw_urdf_exporter -->
<robot
  name="5_degree">
  <link
    name="base_link">
    <inertial>
      <origin
        xyz="-1.3878E-17 1.4057E-08 5.2042E-18"
        rpy="0 0 0" />
      <mass
        value="2.942" />
      <inertia
        ixx="0.0102730"
        ixy="1.2739E-18"
        ixz="-1.5028E-10"
        iyy="0.0389764"
        iyz="8.0721E-18"
        izz="0.0468589" />
    </inertial>
    <visual>
      <origin
        xyz="0 0 0"
        rpy="0 0 0" />
      <geometry>
        <mesh
          filename="package://5_degree/meshes/base_link.STL" />
      </geometry>
      <material
        name="">
        <color
          rgba="1 1 1 1" />
      </material>
    </visual>
    <collision>
      <origin
        xyz="0 0 0"
        rpy="0 0 0" />
      <geometry>
        <mesh
          filename="package://5_degree/meshes/base_link.STL" />
      </geometry>
    </collision>
  </link>
  <link
    name="left_front_link">
    <inertial>
      <origin
        xyz="-2.7801E-08 0.059752 -0.030921"
        rpy="0 0 0" />
      <mass
        value="0.092" />
      <inertia
        ixx="0.0002604"
        ixy="5.1379E-10"
        ixz="9.8825E-10"
        iyy="0.0000502"
        iyz="0.45E-05"
        izz="0.0002599" />
    </inertial>
    <visual>
      <origin
        xyz="0 0 0"
        rpy="0 0 0" />
      <geometry>
        <mesh
          filename="package://5_degree/meshes/left_front_link.STL" />
      </geometry>
      <material
        name="">
        <color
          rgba="1 1 1 1" />
      </material>
    </visual>
    <collision>
      <origin
        xyz="0 0 0"
        rpy="0 0 0" />
      <geometry>
        <mesh
          filename="package://5_degree/meshes/left_front_link.STL" />
      </geometry>
    </collision>
  </link>
  <joint
    name="left_front_leg"
    type="continuous">
    <origin
      xyz="0.13898 0.10261 0"
      rpy="1.5708 1.5708 0" />
    <parent
      link="base_link" />
    <child
      link="left_front_link" />
    <axis
      xyz="0 0.087156 -0.99619" />
    <limit
      effort="5"
      velocity="487" />
  </joint>
  <link
    name="right_front_link">
    <inertial>
      <origin
        xyz="2.7801E-08 0.059752 0.030921"
        rpy="0 0 0" />
      <mass
        value="0.092" />
      <inertia
        ixx="0.0002604"
        ixy="-5.1379E-10"
        ixz="9.8825E-10"
        iyy="0.0000502"
        iyz="-0.45E-05"
        izz="0.0002599" />
    </inertial>
    <visual>
      <origin
        xyz="0 0 0"
        rpy="0 0 0" />
      <geometry>
        <mesh
          filename="package://5_degree/meshes/right_front_link.STL" />
      </geometry>
      <material
        name="">
        <color
          rgba="1 1 1 1" />
      </material>
    </visual>
    <collision>
      <origin
        xyz="0 0 0"
        rpy="0 0 0" />
      <geometry>
        <mesh
          filename="package://5_degree/meshes/right_front_link.STL" />
      </geometry>
    </collision>
  </link>
  <joint
    name="right_front_leg"
    type="continuous">
    <origin
      xyz="0.13898 -0.10261 0"
      rpy="1.5708 1.5708 0" />
    <parent
      link="base_link" />
    <child
      link="right_front_link" />
    <axis
      xyz="0 0.087156 0.99619" />
    <limit
      effort="5"
      velocity="487" />
  </joint>
  <link
    name="right_back_link">
    <inertial>
      <origin
        xyz="6.4028E-09 0.05683 0.03601"
        rpy="0 0 0" />
      <mass
        value="0.092" />
      <inertia
        ixx="0.0002604"
        ixy="-6.7283E-10"
        ixz="6.8545E-10"
        iyy="0.0000526"
        iyz="-2.27E-05"
        izz="0.0002575" />
    </inertial>
    <visual>
      <origin
        xyz="0 0 0"
        rpy="0 0 0" />
      <geometry>
        <mesh
          filename="package://5_degree/meshes/right_back_link.STL" />
      </geometry>
      <material
        name="">
        <color
          rgba="1 1 1 1" />
      </material>
    </visual>
    <collision>
      <origin
        xyz="0 0 0"
        rpy="0 0 0" />
      <geometry>
        <mesh
          filename="package://5_degree/meshes/right_back_link.STL" />
      </geometry>
    </collision>
  </link>
  <joint
    name="right_back_leg"
    type="continuous">
    <origin
      xyz="-0.13898 -0.10261 0"
      rpy="1.6581 1.5708 0" />
    <parent
      link="base_link" />
    <child
      link="right_back_link" />
    <axis
      xyz="0 0 1" />
    <limit
      effort="5"
      velocity="487" />
  </joint>
  <link
    name="left_back_link">
    <inertial>
      <origin
        xyz="-6.4028E-09 0.053475 -0.040826"
        rpy="0 0 0" />
      <mass
        value="0.092" />
      <inertia
        ixx="0.0002604"
        ixy="7.3001E-10"
        ixz="6.242E-10"
        iyy="0.0000581"
        iyz="0.0000401"
        izz="0.0002520" />
    </inertial>
    <visual>
      <origin
        xyz="0 0 0"
        rpy="0 0 0" />
      <geometry>
        <mesh
          filename="package://5_degree/meshes/left_back_link.STL" />
      </geometry>
      <material
        name="">
        <color
          rgba="1 1 1 1" />
      </material>
    </visual>
    <collision>
      <origin
        xyz="0 0 0"
        rpy="0 0 0" />
      <geometry>
        <mesh
          filename="package://5_degree/meshes/left_back_link.STL" />
      </geometry>
    </collision>
  </link>
  <joint
    name="left_back_leg"
    type="continuous">
    <origin
      xyz="-0.13898 0.10261 0"
      rpy="1.5708 1.5708 0" />
    <parent
      link="base_link" />
    <child
      link="left_back_link" />
    <axis
      xyz="0 -0.087156 -0.99619" />
    <limit
      effort="5"
      velocity="487" />
  </joint>
</robot>