<?xml version="1.0" encoding="utf-8"?>
<!-- This URDF was automatically created by SolidWorks to URDF Exporter! Originally created by Stephen Brawner (brawner@gmail.com) 
     Commit Version: 1.5.1-0-g916b5db  Build Version: 1.5.7152.31018
     For more information, please see http://wiki.ros.org/sw_urdf_exporter -->
<robot
  name="4_degree">
  <link
    name="base_link">
    <inertial>
      <origin
        xyz="-2.7756E-17 1.6078E-08 -1.7347E-18"
        rpy="0 0 0" />
      <mass
        value="2.942" />
      <inertia
        ixx="0.0109724"
        ixy="-2.7247E-18"
        ixz="-1.052E-10"
        iyy="0.0378909"
        iyz="2.7757E-19"
        izz="0.0462451" />
    </inertial>
    <visual>
      <origin
        xyz="0 0 0"
        rpy="0 0 0" />
      <geometry>
        <mesh
          filename="package://4_degree/meshes/base_link.STL" />
      </geometry>
      <material
        name="">
        <color
          rgba="1 1 1 1" />
      </material>
    </visual>
    <collision>
      <origin
        xyz="0 0 0"
        rpy="0 0 0" />
      <geometry>
        <mesh
          filename="package://4_degree/meshes/base_link.STL" />
      </geometry>
    </collision>
  </link>
  <link
    name="left_front_link">
    <inertial>
      <origin
        xyz="-2.6147E-08 0.05683 -0.036011"
        rpy="0 0 0" />
      <mass
        value="0.095" />
      <inertia
        ixx="0.0002672"
        ixy="5.8899E-10"
        ixz="9.3094E-10"
        iyy="0.0000540"
        iyz="2.33E-05"
        izz="0.0002642" />
    </inertial>
    <visual>
      <origin
        xyz="0 0 0"
        rpy="0 0 0" />
      <geometry>
        <mesh
          filename="package://4_degree/meshes/left_front_link.STL" />
      </geometry>
      <material
        name="">
        <color
          rgba="1 1 1 1" />
      </material>
    </visual>
    <collision>
      <origin
        xyz="0 0 0"
        rpy="0 0 0" />
      <geometry>
        <mesh
          filename="package://4_degree/meshes/left_front_link.STL" />
      </geometry>
    </collision>
  </link>
  <joint
    name="left_front_leg"
    type="continuous">
    <origin
      xyz="0.13718 0.10275 0"
      rpy="1.6406 1.5708 0" />
    <parent
      link="base_link" />
    <child
      link="left_front_link" />
    <axis
      xyz="0 0 -1" />
    <limit
      effort="5"
      velocity="487" />
  </joint>
  <link
    name="right_front_link">
    <inertial>
      <origin
        xyz="2.6147E-08 0.05683 0.036011"
        rpy="0 0 0" />
      <mass
        value="0.095" />
      <inertia
        ixx="0.0002672"
        ixy="-5.8899E-10"
        ixz="9.3094E-10"
        iyy="0.0000540"
        iyz="-2.33E-05"
        izz="0.0002642" />
    </inertial>
    <visual>
      <origin
        xyz="0 0 0"
        rpy="0 0 0" />
      <geometry>
        <mesh
          filename="package://4_degree/meshes/right_front_link.STL" />
      </geometry>
      <material
        name="">
        <color
          rgba="1 1 1 1" />
      </material>
    </visual>
    <collision>
      <origin
        xyz="0 0 0"
        rpy="0 0 0" />
      <geometry>
        <mesh
          filename="package://4_degree/meshes/right_front_link.STL" />
      </geometry>
    </collision>
  </link>
  <joint
    name="right_front_leg"
    type="continuous">
    <origin
      xyz="0.13718 -0.10275 0"
      rpy="1.501 1.5708 0" />
    <parent
      link="base_link" />
    <child
      link="right_front_link" />
    <axis
      xyz="0 0 1" />
    <limit
      effort="5"
      velocity="487" />
  </joint>
  <link
    name="right_back_link">
    <inertial>
      <origin
        xyz="6.6001E-09 0.05683 0.03601"
        rpy="0 0 0" />
      <mass
        value="0.095" />
      <inertia
        ixx="0.0002672"
        ixy="-6.7247E-10"
        ixz="6.8674E-10"
        iyy="0.0000540"
        iyz="-2.33E-05"
        izz="0.0002642" />
    </inertial>
    <visual>
      <origin
        xyz="0 0 0"
        rpy="0 0 0" />
      <geometry>
        <mesh
          filename="package://4_degree/meshes/right_back_link.STL" />
      </geometry>
      <material
        name="">
        <color
          rgba="1 1 1 1" />
      </material>
    </visual>
    <collision>
      <origin
        xyz="0 0 0"
        rpy="0 0 0" />
      <geometry>
        <mesh
          filename="package://4_degree/meshes/right_back_link.STL" />
      </geometry>
    </collision>
  </link>
  <joint
    name="right_back_leg"
    type="continuous">
    <origin
      xyz="-0.13718 -0.10275 0"
      rpy="1.6406 1.5708 0" />
    <parent
      link="base_link" />
    <child
      link="right_back_link" />
    <axis
      xyz="0 0 1" />
    <limit
      effort="5"
      velocity="487" />
  </joint>
  <link
    name="left_back_link">
    <inertial>
      <origin
        xyz="-6.6001E-09 0.05683 -0.03601"
        rpy="0 0 0" />
      <mass
        value="0.095" />
      <inertia
        ixx="0.0002672"
        ixy="6.7247E-10"
        ixz="6.8674E-10"
        iyy="0.0000540"
        iyz="2.33E-05"
        izz="0.0002642" />
    </inertial>
    <visual>
      <origin
        xyz="0 0 0"
        rpy="0 0 0" />
      <geometry>
        <mesh
          filename="package://4_degree/meshes/left_back_link.STL" />
      </geometry>
      <material
        name="">
        <color
          rgba="1 1 1 1" />
      </material>
    </visual>
    <collision>
      <origin
        xyz="0 0 0"
        rpy="0 0 0" />
      <geometry>
        <mesh
          filename="package://4_degree/meshes/left_back_link.STL" />
      </geometry>
    </collision>
  </link>
  <joint
    name="left_back_leg"
    type="continuous">
    <origin
      xyz="-0.13718 0.10275 0"
      rpy="1.501 1.5708 0" />
    <parent
      link="base_link" />
    <child
      link="left_back_link" />
    <axis
      xyz="0 0 -1" />
    <limit
      effort="5"
      velocity="487" />
  </joint>
</robot>