<?xml version="1.0" encoding="utf-8"?>
<!-- This URDF was automatically created by SolidWorks to URDF Exporter! Originally created by Stephen Brawner (brawner@gmail.com) 
     Commit Version: 1.5.1-0-g916b5db  Build Version: 1.5.7152.31018
     For more information, please see http://wiki.ros.org/sw_urdf_exporter -->
<robot
  name="21_degree">
  <link
    name="base_link">
    <inertial>
      <origin
        xyz="2.0817E-17 4.4852E-08 -1.2476E-08"
        rpy="0 0 0" />
      <mass
        value="2.942" />
      <inertia
        ixx="0.0097283"
        ixy="1.9011E-09"
        ixz="-1.5412E-10"
        iyy="0.0458556"
        iyz="6.6388E-18"
        izz="0.0531702" />
    </inertial>
    <visual>
      <origin
        xyz="0 0 0"
        rpy="0 0 0" />
      <geometry>
        <mesh
          filename="package://21_degree/meshes/base_link.STL" />
      </geometry>
      <material
        name="">
        <color
          rgba="1 1 1 1" />
      </material>
    </visual>
    <collision>
      <origin
        xyz="0 0 0"
        rpy="0 0 0" />
      <geometry>
        <mesh
          filename="package://21_degree/meshes/base_link.STL" />
      </geometry>
    </collision>
  </link>
  <link
    name="left_front_link">
    <inertial>
      <origin
        xyz="-9.6449E-08 0.065963 -0.013251"
        rpy="0 0 0" />
      <mass
        value="0.092" />
      <inertia
        ixx="0.0002604"
        ixy="2.989E-10"
        ixz="7.8444E-10"
        iyy="0.0000638"
        iyz="-0.0000517"
        izz="0.0002464" />
    </inertial>
    <visual>
      <origin
        xyz="0 0 0"
        rpy="0 0 0" />
      <geometry>
        <mesh
          filename="package://21_degree/meshes/left_front_link.STL" />
      </geometry>
      <material
        name="">
        <color
          rgba="1 1 1 1" />
      </material>
    </visual>
    <collision>
      <origin
        xyz="0 0 0"
        rpy="0 0 0" />
      <geometry>
        <mesh
          filename="package://21_degree/meshes/left_front_link.STL" />
      </geometry>
    </collision>
  </link>
  <joint
    name="left_front_leg"
    type="continuous">
    <origin
      xyz="0.16691 0.096159 0"
      rpy="1.5708 1.5708 0" />
    <parent
      link="base_link" />
    <child
      link="left_front_link" />
    <axis
      xyz="0 0.35837 -0.93358" />
    <limit
      effort="5"
      velocity="487" />
  </joint>
  <link
    name="right_front_link">
    <inertial>
      <origin
        xyz="9.6449E-08 0.065963 0.013251"
        rpy="0 0 0" />
      <mass
        value="0.092" />
      <inertia
        ixx="0.0002604"
        ixy="-2.989E-10"
        ixz="7.8444E-10"
        iyy="0.0000638"
        iyz="0.0000517"
        izz="0.0002464" />
    </inertial>
    <visual>
      <origin
        xyz="0 0 0"
        rpy="0 0 0" />
      <geometry>
        <mesh
          filename="package://21_degree/meshes/right_front_link.STL" />
      </geometry>
      <material
        name="">
        <color
          rgba="1 1 1 1" />
      </material>
    </visual>
    <collision>
      <origin
        xyz="0 0 0"
        rpy="0 0 0" />
      <geometry>
        <mesh
          filename="package://21_degree/meshes/right_front_link.STL" />
      </geometry>
    </collision>
  </link>
  <joint
    name="right_front_leg"
    type="continuous">
    <origin
      xyz="0.16691 -0.096159 0"
      rpy="1.5708 1.5708 0" />
    <parent
      link="base_link" />
    <child
      link="right_front_link" />
    <axis
      xyz="0 0.35837 0.93358" />
    <limit
      effort="5"
      velocity="487" />
  </joint>
  <link
    name="right_back_link">
    <inertial>
      <origin
        xyz="8.5928E-08 0.056834 0.03601"
        rpy="0 0 0" />
      <mass
        value="0.092" />
      <inertia
        ixx="0.0002604"
        ixy="-4.8774E-10"
        ixz="5.9078E-10"
        iyy="0.0000526"
        iyz="-2.27E-05"
        izz="0.0002575" />
    </inertial>
    <visual>
      <origin
        xyz="0 0 0"
        rpy="0 0 0" />
      <geometry>
        <mesh
          filename="package://21_degree/meshes/right_back_link.STL" />
      </geometry>
      <material
        name="">
        <color
          rgba="1 1 1 1" />
      </material>
    </visual>
    <collision>
      <origin
        xyz="0 0 0"
        rpy="0 0 0" />
      <geometry>
        <mesh
          filename="package://21_degree/meshes/right_back_link.STL" />
      </geometry>
    </collision>
  </link>
  <joint
    name="right_back_leg"
    type="continuous">
    <origin
      xyz="-0.16691 -0.096159 0"
      rpy="1.9373 1.5708 0" />
    <parent
      link="base_link" />
    <child
      link="right_back_link" />
    <axis
      xyz="0 0 1" />
    <limit
      effort="5"
      velocity="487" />
  </joint>
  <link
    name="left_back_link">
    <inertial>
      <origin
        xyz="-8.5928E-08 0.040154 -0.053986"
        rpy="0 0 0" />
      <mass
        value="0.092" />
      <inertia
        ixx="0.0002604"
        ixy="6.6706E-10"
        ixz="3.7675E-10"
        iyy="0.0000941"
        iyz="0.0000854"
        izz="0.0002160" />
    </inertial>
    <visual>
      <origin
        xyz="0 0 0"
        rpy="0 0 0" />
      <geometry>
        <mesh
          filename="package://21_degree/meshes/left_back_link.STL" />
      </geometry>
      <material
        name="">
        <color
          rgba="1 1 1 1" />
      </material>
    </visual>
    <collision>
      <origin
        xyz="0 0 0"
        rpy="0 0 0" />
      <geometry>
        <mesh
          filename="package://21_degree/meshes/left_back_link.STL" />
      </geometry>
    </collision>
  </link>
  <joint
    name="left_back_leg"
    type="continuous">
    <origin
      xyz="-0.16691 0.096159 0"
      rpy="1.5708 1.5708 0" />
    <parent
      link="base_link" />
    <child
      link="left_back_link" />
    <axis
      xyz="0 -0.35837 -0.93358" />
    <limit
      effort="5"
      velocity="487" />
  </joint>
</robot>